388952
MemoryError

During handling of the above exception, another exception occurred:

Traceback (most recent call last):
  File "c:/Users/bruno/Codigos/Trabalho-IA-aplicada-a-automacao/Profundidade.py", line 29, in <module>
MemoryError